Workbook

Sheet Inputs
A1: PORTFOLIO RISK INTELLIGENCE DASHBOARD - INPUTS
A3: Portfolio Setup
A4: Input Name | B4: Input Value | C4: Notes
A5: Portfolio Name | B5: US Equity Risk Portfolio | C5: Six-stock US equity portfolio
A6: Base Currency | B6: USD | C6: All prices, P&L and risk measures reported in USD
A7: Number of Holdings | B7: 6 | C7: Number of individual stocks
A8: Holdings | B8: AVGO, V, AXP, AMD, MRVL, LLY | C8: Broadcom, Visa, American Express, AMD, Marvell and Eli Lilly
A9: Benchmark | B9: S&P 500 | C9: Benchmark index used for comparison
A10: Data Frequency | B10: Daily | C10: Daily closing-price and return data
A11: Data Start Date | B11: 45505 | C11: First price date in the model
A12: Data End Date | B12: 46234 | C12: Last price date in the model
A14: Risk Model Settings
A15: Input Name | B15: Input Value | C15: Notes
A16: VaR Confidence Level | B16: 0.99 | C16: One-sided confidence level for VaR and Expected Shortfall
A17: VaR Holding Period | B17: 1 | C17: Number of trading days covered by VaR
A18: VaR Holding Period Unit | B18: Days | C18: One-day VaR model
A19: Trading Days per Year | B19: 252 | C19: Annualisation assumption for volatility and return metrics
A20: Parametric Distribution | B20: Normal | C20: Assumption used for parametric VaR and Expected Shortfall
A21: Rolling Volatility Window | B21: 60 | C21: Number of daily observations used for rolling volatility
A22: Rolling Correlation Window | B22: 60 | C22: Number of daily observations used for rolling correlation
A23: EWMA Lambda | B23: 0.94 | C23: Decay factor for EWMA volatility and covariance
A25: Monte Carlo Settings
A26: Input Name | B26: Input Value | C26: Notes
A27: Number of Simulations | B27: 10000 | C27: Number of simulated one-day return scenarios
A28: Random Seed | B28: 12345 | C28: Fixed seed to make simulation outputs reproducible
A29: Simulation Horizon | B29: 1 | C29: Number of trading days in each simulation
A31: Performance Settings
A32: Input Name | B32: Input Value | C32: Notes
A33: Annual Risk-Free Rate | B33: 0.0438 | C33: Average Risk-Free Rate of the last 2 years
A34: Minimum Acceptable Return | B34: 0 | C34: Downside-return threshold used for Sortino ratio
A35: Benchmark Return Series | B35: Benchmark Return | C35: S&P 500 simple daily return column
A36: Performance Return Series | B36: Portfolio Return | C36: Buy-and-hold portfolio simple daily return column
A37: Active Return Definition | B37: Portfolio Return - Benchmark Return | C37: Used for tracking error and Information Ratio

Sheet Prices_Raw

Sheet Returns 
A1: ticker | B1: price_date | C1: close_price | D1: prior_close_price | E1: simple_return | F1: log_return | H1: Date | I1: AMD | J1: AVGO | K1: AXP | L1: LLY | M1: MRVL | N1: V
A2: AMD | B2: 45506 | C2: 132.5 | D2: 132.54 | E2: -0.000301796 | F2: -0.000301841 | H2: {=_xlfn._xlws.SORT(_xlfn.UNIQUE($B$2:$B$3001))} -> 45506 | I2: {=_xlfn.XLOOKUP(1,($A$2:$A$3001=I$1)*($B$2:$B$3001=$H2),$E$2:$E$3001,"")} -> -0.000301796 | J2: {=_xlfn.XLOOKUP(1,(returns__6[ticker]=$J$1)*(returns__6[price_date]=H2),returns__6[simple_return],"")} -> -0.021765746 | K2: {=_xlfn.XLOOKUP(1,(returns__6[ticker]=$K$1)*(returns__6[price_date]=H2),returns__6[simple_return],"")} -> -0.065948207 | L2: {=_xlfn.XLOOKUP(1,(returns__6[ticker]=$L$1)*(returns__6[price_date]=H2),returns__6[simple_return],"")} -> -0.033612032 | M2: {=_xlfn.XLOOKUP(1,(returns__6[ticker]=$M$1)*(returns__6[price_date]=H2),returns__6[simple_return],"")} -> -0.060418649 | N2: {=_xlfn.XLOOKUP(1,(returns__6[ticker]=$N$1)*(returns__6[price_date]=H2),returns__6[simple_return],"")} -> 0.002444252
A3: AVGO | B3: 45506 | C3: 143.82 | D3: 147.02 | E3: -0.021765746 | F3: -0.022006114 | H3: 45509 | I3: {=_xlfn.XLOOKUP(1,($A$2:$A$3001=I$1)*($B$2:$B$3001=$H3),$E$2:$E$3001,"")} -> 0.017509434 | J3: {=_xlfn.XLOOKUP(1,(returns__6[ticker]=$J$1)*(returns__6[price_date]=H3),returns__6[simple_return],"")} -> -0.012098456 | K3: {=_xlfn.XLOOKUP(1,(returns__6[ticker]=$K$1)*(returns__6[price_date]=H3),returns__6[simple_return],"")} -> -0.027380747 | L3: {=_xlfn.XLOOKUP(1,(returns__6[ticker]=$L$1)*(returns__6[price_date]=H3),returns__6[simple_return],"")} -> -0.036297641 | M3: {=_xlfn.XLOOKUP(1,(returns__6[ticker]=$M$1)*(returns__6[price_date]=H3),returns__6[simple_return],"")} -> -0.026666667 | N3: {=_xlfn.XLOOKUP(1,(returns__6[ticker]=$N$1)*(returns__6[price_date]=H3),returns__6[simple_return],"")} -> -0.038037362
A4: AXP | B4: 45506 | C4: 232.28 | D4: 248.68 | E4: -0.065948207 | F4: -0.068223389 | H4: 45510 | I4: {=_xlfn.XLOOKUP(1,($A$2:$A$3001=I$1)*($B$2:$B$3001=$H4),$E$2:$E$3001,"")} -> -0.034416259 | J4: {=_xlfn.XLOOKUP(1,(returns__6[ticker]=$J$1)*(returns__6[price_date]=H4),returns__6[simple_return],"")} -> 0.012950451 | K4: {=_xlfn.XLOOKUP(1,(returns__6[ticker]=$K$1)*(returns__6[price_date]=H4),returns__6[simple_return],"")} -> 0.023016997 | L4: {=_xlfn.XLOOKUP(1,(returns__6[ticker]=$L$1)*(returns__6[price_date]=H4),returns__6[simple_return],"")} -> 0.023114826 | M4: {=_xlfn.XLOOKUP(1,(returns__6[ticker]=$M$1)*(returns__6[price_date]=H4),returns__6[simple_return],"")} -> 0.009537021 | N4: {=_xlfn.XLOOKUP(1,(returns__6[ticker]=$N$1)*(returns__6[price_date]=H4),returns__6[simple_return],"")} -> 0.007097177
A5: LLY | B5: 45506 | C5: 804.46 | D5: 832.44 | E5: -0.033612032 | F5: -0.034189902 | H5: 45511 | I5: {=_xlfn.XLOOKUP(1,($A$2:$A$3001=I$1)*($B$2:$B$3001=$H5),$E$2:$E$3001,"")} -> -0.011599324 | J5: {=_xlfn.XLOOKUP(1,(returns__6[ticker]=$J$1)*(returns__6[price_date]=H5),returns__6[simple_return],"")} -> -0.05315453 | K5: {=_xlfn.XLOOKUP(1,(returns__6[ticker]=$K$1)*(returns__6[price_date]=H5),returns__6[simple_return],"")} -> -0.010038076 | L5: {=_xlfn.XLOOKUP(1,(returns__6[ticker]=$L$1)*(returns__6[price_date]=H5),returns__6[simple_return],"")} -> -0.026526135 | M5: {=_xlfn.XLOOKUP(1,(returns__6[ticker]=$M$1)*(returns__6[price_date]=H5),returns__6[simple_return],"")} -> -0.035554792 | N5: {=_xlfn.XLOOKUP(1,(returns__6[ticker]=$N$1)*(returns__6[price_date]=H5),returns__6[simple_return],"")} -> -0.006737396
A6: MRVL | B6: 45506 | C6: 59.25 | D6: 63.06 | E6: -0.060418649 | F6: -0.062320874 | H6: 45512 | I6: {=_xlfn.XLOOKUP(1,($A$2:$A$3001=I$1)*($B$2:$B$3001=$H6),$E$2:$E$3001,"")} -> 0.059454418 | J6: {=_xlfn.XLOOKUP(1,(returns__6[ticker]=$J$1)*(returns__6[price_date]=H6),returns__6[simple_return],"")} -> 0.069494386 | K6: {=_xlfn.XLOOKUP(1,(returns__6[ticker]=$K$1)*(returns__6[price_date]=H6),returns__6[simple_return],"")} -> 0.020716783 | L6: {=_xlfn.XLOOKUP(1,(returns__6[ticker]=$L$1)*(returns__6[price_date]=H6),returns__6[simple_return],"")} -> 0.094762608 | M6: {=_xlfn.XLOOKUP(1,(returns__6[ticker]=$M$1)*(returns__6[price_date]=H6),returns__6[simple_return],"")} -> 0.089225289 | N6: {=_xlfn.XLOOKUP(1,(returns__6[ticker]=$N$1)*(returns__6[price_date]=H6),returns__6[simple_return],"")} -> 0.012903477
A7: V | B7: 45506 | C7: 266.58 | D7: 265.93 | E7: 0.002444252 | F7: 0.00244127 | H7: 45513 | I7: {=_xlfn.XLOOKUP(1,($A$2:$A$3001=I$1)*($B$2:$B$3001=$H7),$E$2:$E$3001,"")} -> -0.015038146 | J7: {=_xlfn.XLOOKUP(1,(returns__6[ticker]=$J$1)*(returns__6[price_date]=H7),returns__6[simple_return],"")} -> 0.017291066 | K7: {=_xlfn.XLOOKUP(1,(returns__6[ticker]=$K$1)*(returns__6[price_date]=H7),returns__6[simple_return],"")} -> 0.018455083 | L7: {=_xlfn.XLOOKUP(1,(returns__6[ticker]=$L$1)*(returns__6[price_date]=H7),returns__6[simple_return],"")} -> 0.054855615 | M7: {=_xlfn.XLOOKUP(1,(returns__6[ticker]=$M$1)*(returns__6[price_date]=H7),returns__6[simple_return],"")} -> -0.009810334 | N7: {=_xlfn.XLOOKUP(1,(returns__6[ticker]=$N$1)*(returns__6[price_date]=H7),returns__6[simple_return],"")} -> -0.000269407
A8: AMD | B8: 45509 | C8: 134.82 | D8: 132.5 | E8: 0.017509434 | F8: 0.01735791 | H8: 45516 | I8: {=_xlfn.XLOOKUP(1,($A$2:$A$3001=I$1)*($B$2:$B$3001=$H8),$E$2:$E$3001,"")} -> 0.0186192 | J8: {=_xlfn.XLOOKUP(1,(returns__6[ticker]=$J$1)*(returns__6[price_date]=H8),returns__6[simple_return],"")} -> 0.002428167 | K8: {=_xlfn.XLOOKUP(1,(returns__6[ticker]=$K$1)*(returns__6[price_date]=H8),returns__6[simple_return],"")} -> -0.003363464 | L8: {=_xlfn.XLOOKUP(1,(returns__6[ticker]=$L$1)*(returns__6[price_date]=H8),returns__6[simple_return],"")} -> -0.008186794 | M8: {=_xlfn.XLOOKUP(1,(returns__6[ticker]=$M$1)*(returns__6[price_date]=H8),returns__6[simple_return],"")} -> -0.000825628 | N8: {=_xlfn.XLOOKUP(1,(returns__6[ticker]=$N$1)*(returns__6[price_date]=H8),returns__6[simple_return],"")} -> 0.000500462
A9: AVGO | B9: 45509 | C9: 142.08 | D9: 143.82 | E9: -0.012098456 | F9: -0.012172238 | H9: 45517 | I9: {=_xlfn.XLOOKUP(1,($A$2:$A$3001=I$1)*($B$2:$B$3001=$H9),$E$2:$E$3001,"")} -> 0.031878336 | J9: {=_xlfn.XLOOKUP(1,(returns__6[ticker]=$J$1)*(returns__6[price_date]=H9),returns__6[simple_return],"")} -> 0.050733414 | K9: {=_xlfn.XLOOKUP(1,(returns__6[ticker]=$K$1)*(returns__6[price_date]=H9),returns__6[simple_return],"")} -> 0.008183927 | L9: {=_xlfn.XLOOKUP(1,(returns__6[ticker]=$L$1)*(returns__6[price_date]=H9),returns__6[simple_return],"")} -> 0.026764513 | M9: {=_xlfn.XLOOKUP(1,(returns__6[ticker]=$M$1)*(returns__6[price_date]=H9),returns__6[simple_return],"")} -> 0.058502727 | N9: {=_xlfn.XLOOKUP(1,(returns__6[ticker]=$N$1)*(returns__6[price_date]=H9),returns__6[simple_return],"")} -> 0.000923468
A10: AXP | B10: 45509 | C10: 225.92 | D10: 232.28 | E10: -0.027380747 | F10: -0.027762586 | H10: 45518 | I10: {=_xlfn.XLOOKUP(1,($A$2:$A$3001=I$1)*($B$2:$B$3001=$H10),$E$2:$E$3001,"")} -> -0.002692553 | J10: {=_xlfn.XLOOKUP(1,(returns__6[ticker]=$J$1)*(returns__6[price_date]=H10),returns__6[simple_return],"")} -> 0.009797643 | K10: {=_xlfn.XLOOKUP(1,(returns__6[ticker]=$K$1)*(returns__6[price_date]=H10),returns__6[simple_return],"")} -> 0.019958994 | L10: {=_xlfn.XLOOKUP(1,(returns__6[ticker]=$L$1)*(returns__6[price_date]=H10),returns__6[simple_return],"")} -> 0.026022796 | M10: {=_xlfn.XLOOKUP(1,(returns__6[ticker]=$M$1)*(returns__6[price_date]=H10),returns__6[simple_return],"")} -> -0.004059329 | N10: {=_xlfn.XLOOKUP(1,(returns__6[ticker]=$N$1)*(returns__6[price_date]=H10),returns__6[simple_return],"")} -> 0.003882674
A11: LLY | B11: 45509 | C11: 775.26 | D11: 804.46 | E11: -0.036297641 | F11: -0.036972788 | H11: 45519 | I11: {=_xlfn.XLOOKUP(1,($A$2:$A$3001=I$1)*($B$2:$B$3001=$H11),$E$2:$E$3001,"")} -> 0.0469627 | J11: {=_xlfn.XLOOKUP(1,(returns__6[ticker]=$J$1)*(returns__6[price_date]=H11),returns__6[simple_return],"")} -> 0.053522735 | K11: {=_xlfn.XLOOKUP(1,(returns__6[ticker]=$K$1)*(returns__6[price_date]=H11),returns__6[simple_return],"")} -> 0.023547752 | L11: {=_xlfn.XLOOKUP(1,(returns__6[ticker]=$L$1)*(returns__6[price_date]=H11),returns__6[simple_return],"")} -> -0.000107333 | M11: {=_xlfn.XLOOKUP(1,(returns__6[ticker]=$M$1)*(returns__6[price_date]=H11),returns__6[simple_return],"")} -> 0.086847468 | N11: {=_xlfn.XLOOKUP(1,(returns__6[ticker]=$N$1)*(returns__6[price_date]=H11),returns__6[simple_return],"")} -> 0.021674198
A12: MRVL | B12: 45509 | C12: 57.67 | D12: 59.25 | E12: -0.026666667 | F12: -0.027028672 | H12: 45520 | I12: {=_xlfn.XLOOKUP(1,($A$2:$A$3001=I$1)*($B$2:$B$3001=$H12),$E$2:$E$3001,"")} -> 0.008143323 | J12: {=_xlfn.XLOOKUP(1,(returns__6[ticker]=$J$1)*(returns__6[price_date]=H12),returns__6[simple_return],"")} -> -0.002467947 | K12: {=_xlfn.XLOOKUP(1,(returns__6[ticker]=$K$1)*(returns__6[price_date]=H12),returns__6[simple_return],"")} -> 0.008857715 | L12: {=_xlfn.XLOOKUP(1,(returns__6[ticker]=$L$1)*(returns__6[price_date]=H12),returns__6[simple_return],"")} -> -0.010154791 | M12: {=_xlfn.XLOOKUP(1,(returns__6[ticker]=$M$1)*(returns__6[price_date]=H12),returns__6[simple_return],"")} -> -0.000144238 | N12: {=_xlfn.XLOOKUP(1,(returns__6[ticker]=$N$1)*(returns__6[price_date]=H12),returns__6[simple_return],"")} -> 0.002173913
A13: V | B13: 45509 | C13: 256.44 | D13: 266.58 | E13: -0.038037362 | F13: -0.038779667 | H13: 45523 | I13: {=_xlfn.XLOOKUP(1,($A$2:$A$3001=I$1)*($B$2:$B$3001=$H13),$E$2:$E$3001,"")} -> 0.045234249 | J13: {=_xlfn.XLOOKUP(1,(returns__6[ticker]=$J$1)*(returns__6[price_date]=H13),returns__6[simple_return],"")} -> 0.012008207 | K13: {=_xlfn.XLOOKUP(1,(returns__6[ticker]=$K$1)*(returns__6[price_date]=H13),returns__6[simple_return],"")} -> 0.009296413 | L13: {=_xlfn.XLOOKUP(1,(returns__6[ticker]=$L$1)*(returns__6[price_date]=H13),returns__6[simple_return],"")} -> -0.000336182 | M13: {=_xlfn.XLOOKUP(1,(returns__6[ticker]=$M$1)*(returns__6[price_date]=H13),returns__6[simple_return],"")} -> 0.024812464 | N13: {=_xlfn.XLOOKUP(1,(returns__6[ticker]=$N$1)*(returns__6[price_date]=H13),returns__6[simple_return],"")} -> -0.003403396
A14: AMD | B14: 45510 | C14: 130.18 | D14: 134.82 | E14: -0.034416259 | F14: -0.035022447 | H14: 45524 | I14: {=_xlfn.XLOOKUP(1,($A$2:$A$3001=I$1)*($B$2:$B$3001=$H14),$E$2:$E$3001,"")} -> 0.007212777 | J14: {=_xlfn.XLOOKUP(1,(returns__6[ticker]=$J$1)*(returns__6[price_date]=H14),returns__6[simple_return],"")} -> -0.010494306 | K14: {=_xlfn.XLOOKUP(1,(returns__6[ticker]=$K$1)*(returns__6[price_date]=H14),returns__6[simple_return],"")} -> -0.003818146 | L14: {=_xlfn.XLOOKUP(1,(returns__6[ticker]=$L$1)*(returns__6[price_date]=H14),returns__6[simple_return],"")} -> 0.030548595 | M14: {=_xlfn.XLOOKUP(1,(returns__6[ticker]=$M$1)*(returns__6[price_date]=H14),returns__6[simple_return],"")} -> -0.02294482 | N14: {=_xlfn.XLOOKUP(1,(returns__6[ticker]=$N$1)*(returns__6[price_date]=H14),returns__6[simple_return],"")} -> 0.005891845
... A501: AVGO | B501: 45625 | C501: 162.08 | D501: 159.67 | E501: 0.015093631 | F501: 0.014980855 | H501: 46234 | I501: {=_xlfn.XLOOKUP(1,($A$2:$A$3001=I$1)*($B$2:$B$3001=$H501),$E$2:$E$3001,"")} -> -0.019036239 | J501: {=_xlfn.XLOOKUP(1,(returns__6[ticker]=$J$1)*(returns__6[price_date]=H501),returns__6[simple_return],"")} -> 0.003712871 | K501: {=_xlfn.XLOOKUP(1,(returns__6[ticker]=$K$1)*(returns__6[price_date]=H501),returns__6[simple_return],"")} -> -0.00376274 | L501: {=_xlfn.XLOOKUP(1,(returns__6[ticker]=$L$1)*(returns__6[price_date]=H501),returns__6[simple_return],"")} -> -0.005307497 | M501: {=_xlfn.XLOOKUP(1,(returns__6[ticker]=$M$1)*(returns__6[price_date]=H501),returns__6[simple_return],"")} -> 0.023240589 | N501: {=_xlfn.XLOOKUP(1,(returns__6[ticker]=$N$1)*(returns__6[price_date]=H501),returns__6[simple_return],"")} -> -0.000382232
A502: AXP | B502: 45625 | C502: 304.68 | D502: 304.25 | E502: 0.001413311 | F502: 0.001412314
A503: LLY | B503: 45625 | C503: 795.35 | D503: 788.19 | E503: 0.009084104 | F503: 0.009043092
A504: MRVL | B504: 45625 | C504: 92.69 | D504: 90.1 | E504: 0.028745838 | F504: 0.028340427
A505: V | B505: 45625 | C505: 315.08 | D505: 314.7 | E505: 0.001207499 | F505: 0.001206771
A506: AMD | B506: 45628 | C506: 142.06 | D506: 137.18 | E506: 0.035573699 | F506: 0.034955571
A507: AVGO | B507: 45628 | C507: 166.51 | D507: 162.08 | E507: 0.027332182 | F507: 0.026965327
A508: AXP | B508: 45628 | C508: 302.26 | D508: 304.68 | E508: -0.00794276 | F508: -0.007974471
A509: LLY | B509: 45628 | C509: 799.8 | D509: 795.35 | E509: 0.005595021 | F509: 0.005579427
A510: MRVL | B510: 45628 | C510: 96.86 | D510: 92.69 | E510: 0.044988672 | F510: 0.044006045
A511: V | B511: 45628 | C511: 316.65 | D511: 315.08 | E511: 0.004982862 | F511: 0.004970488
A512: AMD | B512: 45629 | C512: 141.98 | D512: 142.06 | E512: -0.000563142 | F512: -0.000563301
A513: AVGO | B513: 45629 | C513: 168.15 | D513: 166.51 | E513: 0.009849258 | F513: 0.009801071
... A3001: V | B3001: 46234 | C3001: 366.13 | D3001: 366.27 | E3001: -0.000382232 | F3001: -0.000382305

Sheet Portfolio_Returns
A1: price_date | B1: port_mv | C1: previous_day_mv | D1: daily_pnl_usd | E1: portfolio_simple_return | F1: B.simple_return | G1: B.log_return | H1: Active_return
A2: 45506 | B2: 97035.16 | C2: 100025.09 | D2: -2989.93 | E2: -0.0298918 | F2: -0.01838184 | G2: -0.018552885 | H2: =returns_pnl[[#This Row],[portfolio_simple_return]]-returns_pnl[[#This Row],[B.simple_return]] -> -0.01150996
A3: 45509 | B3: 95064.8 | C3: 97035.16 | D3: -1970.36 | E3: -0.020305629 | F3: -0.0299688 | G3: -0.030427045 | H3: =returns_pnl[[#This Row],[portfolio_simple_return]]-returns_pnl[[#This Row],[B.simple_return]] -> 0.009663171
A4: 45510 | B4: 95654.74 | C4: 95064.8 | D4: 589.94 | E4: 0.006205662 | F4: 0.01035414 | G4: 0.010300906 | H4: =returns_pnl[[#This Row],[portfolio_simple_return]]-returns_pnl[[#This Row],[B.simple_return]] -> -0.004148478
A5: 45511 | B5: 93367.69 | C5: 95654.74 | D5: -2287.05 | E5: -0.023909427 | F5: -0.00773469 | G5: -0.0077647564 | H5: =returns_pnl[[#This Row],[portfolio_simple_return]]-returns_pnl[[#This Row],[B.simple_return]] -> -0.016174737
A6: 45512 | B6: 98713.85 | C6: 93367.69 | D6: 5346.16 | E6: 0.057259208 | F6: 0.0230426 | G6: 0.022781129 | H6: =returns_pnl[[#This Row],[portfolio_simple_return]]-returns_pnl[[#This Row],[B.simple_return]] -> 0.034216608
A7: 45513 | B7: 99793.67 | C7: 98713.85 | D7: 1079.82 | E7: 0.010938891 | F7: 0.00467166 | G7: 0.0046607802 | H7: =returns_pnl[[#This Row],[portfolio_simple_return]]-returns_pnl[[#This Row],[B.simple_return]] -> 0.006267231
A8: 45516 | B8: 99944.74 | C8: 99793.67 | D8: 151.07 | E8: 0.001513824 | F8: 4.304e-05 | G8: 4.3036708e-05 | H8: =returns_pnl[[#This Row],[portfolio_simple_return]]-returns_pnl[[#This Row],[B.simple_return]] -> 0.001470784
A9: 45517 | B9: 102899.18 | C9: 99944.74 | D9: 2954.44 | E9: 0.029560735 | F9: 0.01684757 | G9: 0.016707227 | H9: =returns_pnl[[#This Row],[portfolio_simple_return]]-returns_pnl[[#This Row],[B.simple_return]] -> 0.012713165
A10: 45518 | B10: 103811.37 | C10: 102899.18 | D10: 912.19 | E10: 0.008864891 | F10: 0.00382377 | G10: 0.0038164761 | H10: =returns_pnl[[#This Row],[portfolio_simple_return]]-returns_pnl[[#This Row],[B.simple_return]] -> 0.005041121
A11: 45519 | B11: 107799.67 | C11: 103811.37 | D11: 3988.3 | E11: 0.03841872 | F11: 0.0161332 | G11: 0.016004444 | H11: =returns_pnl[[#This Row],[portfolio_simple_return]]-returns_pnl[[#This Row],[B.simple_return]] -> 0.02228552
A12: 45520 | B12: 107897.31 | C12: 107799.67 | D12: 97.64 | E12: 0.000905754 | F12: 0.00198982 | G12: 0.0019878411 | H12: =returns_pnl[[#This Row],[portfolio_simple_return]]-returns_pnl[[#This Row],[B.simple_return]] -> -0.001084066
A13: 45523 | B13: 109516.23 | C13: 107897.31 | D13: 1618.92 | E13: 0.015004267 | F13: 0.00972228 | G13: 0.0096753274 | H13: =returns_pnl[[#This Row],[portfolio_simple_return]]-returns_pnl[[#This Row],[B.simple_return]] -> 0.005281987
... A501: 46234 | B501: 222071.12 | C501: 222164.51 | D501: -93.39 | E501: -0.000420364 | F501: 0.00700358 | G501: 0.0069791639 | H501: =returns_pnl[[#This Row],[portfolio_simple_return]]-returns_pnl[[#This Row],[B.simple_return]] -> -0.007423944

Sheet Old Portfolio return
A1: price_date | B1: P.avg(simple_return) | C1: P.avg(log_return) | D1: B.simple_return | E1: B.log_return
A2: 45506 | B2: -0.029933696 | C2: -0.030766808 | D2: -0.01838184 | E2: -0.018552885
A3: 45509 | B3: -0.02049524 | C3: -0.020893007 | D3: -0.0299688 | E3: -0.030427045
A4: 45510 | B4: 0.0068833688 | C4: 0.0066694385 | D4: 0.01035414 | E4: 0.010300906
A5: 45511 | B5: -0.023935042 | C5: -0.024370342 | D5: -0.00773469 | E5: -0.0077647564
A6: 45512 | B6: 0.057759494 | C6: 0.055711728 | D6: 0.0230426 | E6: 0.022781129
A7: 45513 | B7: 0.01091398 | C7: 0.010592242 | D7: 0.00467166 | E7: 0.0046607802
A8: 45516 | B8: 0.0015286572 | C8: 0.0014929923 | D8: 4.304e-05 | E8: 4.3036708e-05
A9: 45517 | B9: 0.029497731 | C9: 0.028868473 | D9: 0.01684757 | E9: 0.016707227
A10: 45518 | B10: 0.008818371 | C10: 0.0087189548 | D10: 0.00382377 | E10: 0.0038164761
A11: 45519 | B11: 0.038741253 | C11: 0.037654035 | D11: 0.0161332 | E11: 0.016004444
A12: 45520 | B12: 0.0010679959 | C12: 0.0010464444 | D12: 0.00198982 | E12: 0.0019878411
A13: 45523 | B13: 0.014601959 | C13: 0.014365894 | D13: 0.00972228 | E13: 0.0096753274
... A501: 46234 | B501: -0.00025587455 | C501: -0.00033548325 | D501: 0.00700358 | E501: 0.0069791639

Sheet Rolling_Corr
A1: Date | B1: AMD-AVGO 60D CORRELATION | C1: AMD-MRVL 60D CORRELATION | D1: AXP-V 60D CORRELATION
A2: =returns_pnl[[#This Row],[price_date]] -> 45506
A3: =returns_pnl[[#This Row],[price_date]] -> 45509
A4: =returns_pnl[[#This Row],[price_date]] -> 45510
A5: =returns_pnl[[#This Row],[price_date]] -> 45511
A6: =returns_pnl[[#This Row],[price_date]] -> 45512
A7: =returns_pnl[[#This Row],[price_date]] -> 45513
A8: =returns_pnl[[#This Row],[price_date]] -> 45516
A9: =returns_pnl[[#This Row],[price_date]] -> 45517
A10: =returns_pnl[[#This Row],[price_date]] -> 45518
A11: =returns_pnl[[#This Row],[price_date]] -> 45519
A12: =returns_pnl[[#This Row],[price_date]] -> 45520
A13: =returns_pnl[[#This Row],[price_date]] -> 45523
... A60: =returns_pnl[[#This Row],[price_date]] -> 45589
A61: =returns_pnl[[#This Row],[price_date]] -> 45590 | B61: =CORREL('Returns '!I2:I61,'Returns '!J2:J61) -> 0.70965863 | C61: =CORREL('Returns '!I2:I61,'Returns '!M2:M61) -> 0.64927207 | D61: =CORREL('Returns '!K2:K61,'Returns '!N2:N61) -> 0.28201259
A62: =returns_pnl[[#This Row],[price_date]] -> 45593 | B62: =CORREL('Returns '!I3:I62,'Returns '!J3:J62) -> 0.70439234 | C62: =CORREL('Returns '!I3:I62,'Returns '!M3:M62) -> 0.66827917 | D62: =CORREL('Returns '!K3:K62,'Returns '!N3:N62) -> 0.34010522
A63: =returns_pnl[[#This Row],[price_date]] -> 45594 | B63: =CORREL('Returns '!I4:I63,'Returns '!J4:J63) -> 0.71997675 | C63: =CORREL('Returns '!I4:I63,'Returns '!M4:M63) -> 0.68086751 | D63: =CORREL('Returns '!K4:K63,'Returns '!N4:N63) -> 0.27067955
A64: =returns_pnl[[#This Row],[price_date]] -> 45595 | B64: =CORREL('Returns '!I5:I64,'Returns '!J5:J64) -> 0.68898437 | C64: =CORREL('Returns '!I5:I64,'Returns '!M5:M64) -> 0.66677661 | D64: =CORREL('Returns '!K5:K64,'Returns '!N5:N64) -> 0.27930798
A65: =returns_pnl[[#This Row],[price_date]] -> 45596 | B65: =CORREL('Returns '!I6:I65,'Returns '!J6:J65) -> 0.70341189 | C65: =CORREL('Returns '!I6:I65,'Returns '!M6:M65) -> 0.67424582 | D65: =CORREL('Returns '!K6:K65,'Returns '!N6:N65) -> 0.27323549
A66: =returns_pnl[[#This Row],[price_date]] -> 45597 | B66: =CORREL('Returns '!I7:I66,'Returns '!J7:J66) -> 0.68261736 | C66: =CORREL('Returns '!I7:I66,'Returns '!M7:M66) -> 0.61677061 | D66: =CORREL('Returns '!K7:K66,'Returns '!N7:N66) -> 0.25979547
A67: =returns_pnl[[#This Row],[price_date]] -> 45600 | B67: =CORREL('Returns '!I8:I67,'Returns '!J8:J67) -> 0.69049672 | C67: =CORREL('Returns '!I8:I67,'Returns '!M8:M67) -> 0.61570828 | D67: =CORREL('Returns '!K8:K67,'Returns '!N8:N67) -> 0.26250431
A68: =returns_pnl[[#This Row],[price_date]] -> 45601 | B68: =CORREL('Returns '!I9:I68,'Returns '!J9:J68) -> 0.68981561 | C68: =CORREL('Returns '!I9:I68,'Returns '!M9:M68) -> 0.61872756 | D68: =CORREL('Returns '!K9:K68,'Returns '!N9:N68) -> 0.26348427
A69: =returns_pnl[[#This Row],[price_date]] -> 45602 | B69: =CORREL('Returns '!I10:I69,'Returns '!J10:J69) -> 0.68686748 | C69: =CORREL('Returns '!I10:I69,'Returns '!M10:M69) -> 0.61454205 | D69: =CORREL('Returns '!K10:K69,'Returns '!N10:N69) -> 0.43064131
A70: =returns_pnl[[#This Row],[price_date]] -> 45603 | B70: =CORREL('Returns '!I11:I70,'Returns '!J11:J70) -> 0.69117199 | C70: =CORREL('Returns '!I11:I70,'Returns '!M11:M70) -> 0.62079631 | D70: =CORREL('Returns '!K11:K70,'Returns '!N11:N70) -> 0.43778107
A71: =returns_pnl[[#This Row],[price_date]] -> 45604 | B71: =CORREL('Returns '!I12:I71,'Returns '!J12:J71) -> 0.67647896 | C71: =CORREL('Returns '!I12:I71,'Returns '!M12:M71) -> 0.60073416 | D71: =CORREL('Returns '!K12:K71,'Returns '!N12:N71) -> 0.42082097
A72: =returns_pnl[[#This Row],[price_date]] -> 45607 | B72: =CORREL('Returns '!I13:I72,'Returns '!J13:J72) -> 0.67461985 | C72: =CORREL('Returns '!I13:I72,'Returns '!M13:M72) -> 0.60112112 | D72: =CORREL('Returns '!K13:K72,'Returns '!N13:N72) -> 0.42608411
... A501: =returns_pnl[[#This Row],[price_date]] -> 46234 | B501: =CORREL('Returns '!I442:I501,'Returns '!J442:J501) -> 0.58545773 | C501: =CORREL('Returns '!I442:I501,'Returns '!M442:M501) -> 0.66546774 | D501: =CORREL('Returns '!K442:K501,'Returns '!N442:N501) -> 0.40986739

Sheet Rolling_Vol
A1: Date | B1: Portfolio Daily Return | C1: 60-Day Rolling Daily Volatility | D1: 60-Day Rolling Annualized Volatility
A2: =returns_pnl[[#This Row],[price_date]] -> 45506 | B2: =returns_pnl[[#This Row],[portfolio_simple_return]] -> -0.0298918
A3: =returns_pnl[[#This Row],[price_date]] -> 45509 | B3: =returns_pnl[[#This Row],[portfolio_simple_return]] -> -0.020305629
A4: =returns_pnl[[#This Row],[price_date]] -> 45510 | B4: =returns_pnl[[#This Row],[portfolio_simple_return]] -> 0.006205662
A5: =returns_pnl[[#This Row],[price_date]] -> 45511 | B5: =returns_pnl[[#This Row],[portfolio_simple_return]] -> -0.023909427
A6: =returns_pnl[[#This Row],[price_date]] -> 45512 | B6: =returns_pnl[[#This Row],[portfolio_simple_return]] -> 0.057259208
A7: =returns_pnl[[#This Row],[price_date]] -> 45513 | B7: =returns_pnl[[#This Row],[portfolio_simple_return]] -> 0.010938891
A8: =returns_pnl[[#This Row],[price_date]] -> 45516 | B8: =returns_pnl[[#This Row],[portfolio_simple_return]] -> 0.001513824
A9: =returns_pnl[[#This Row],[price_date]] -> 45517 | B9: =returns_pnl[[#This Row],[portfolio_simple_return]] -> 0.029560735
A10: =returns_pnl[[#This Row],[price_date]] -> 45518 | B10: =returns_pnl[[#This Row],[portfolio_simple_return]] -> 0.008864891
A11: =returns_pnl[[#This Row],[price_date]] -> 45519 | B11: =returns_pnl[[#This Row],[portfolio_simple_return]] -> 0.03841872
A12: =returns_pnl[[#This Row],[price_date]] -> 45520 | B12: =returns_pnl[[#This Row],[portfolio_simple_return]] -> 0.000905754
A13: =returns_pnl[[#This Row],[price_date]] -> 45523 | B13: =returns_pnl[[#This Row],[portfolio_simple_return]] -> 0.015004267
... A60: =returns_pnl[[#This Row],[price_date]] -> 45589 | B60: =returns_pnl[[#This Row],[portfolio_simple_return]] -> -0.004426799
A61: =returns_pnl[[#This Row],[price_date]] -> 45590 | B61: =returns_pnl[[#This Row],[portfolio_simple_return]] -> 0.001849787 | C61: =_xlfn.STDEV.S(B2:B61) -> 0.017671267 | D61: =C61*SQRT(252) -> 0.28052267
A62: =returns_pnl[[#This Row],[price_date]] -> 45593 | B62: =returns_pnl[[#This Row],[portfolio_simple_return]] -> 0.011602837 | C62: =_xlfn.STDEV.S(B3:B62) -> 0.017192439 | D62: =C62*SQRT(252) -> 0.27292151
A63: =returns_pnl[[#This Row],[price_date]] -> 45594 | B63: =returns_pnl[[#This Row],[portfolio_simple_return]] -> 0.016740529 | C63: =_xlfn.STDEV.S(B4:B63) -> 0.017002915 | D63: =C63*SQRT(252) -> 0.2699129
A64: =returns_pnl[[#This Row],[price_date]] -> 45595 | B64: =returns_pnl[[#This Row],[portfolio_simple_return]] -> -0.029202981 | C64: =_xlfn.STDEV.S(B5:B64) -> 0.017520618 | D64: =C64*SQRT(252) -> 0.27813119
A65: =returns_pnl[[#This Row],[price_date]] -> 45596 | B65: =returns_pnl[[#This Row],[portfolio_simple_return]] -> -0.023541059 | C65: =_xlfn.STDEV.S(B6:B65) -> 0.017511056 | D65: =C65*SQRT(252) -> 0.2779794
A66: =returns_pnl[[#This Row],[price_date]] -> 45597 | B66: =returns_pnl[[#This Row],[portfolio_simple_return]] -> 0.007811349 | C66: =_xlfn.STDEV.S(B7:B66) -> 0.016019109 | D66: =C66*SQRT(252) -> 0.25429548
A67: =returns_pnl[[#This Row],[price_date]] -> 45600 | B67: =returns_pnl[[#This Row],[portfolio_simple_return]] -> -0.005725731 | C67: =_xlfn.STDEV.S(B8:B67) -> 0.016010879 | D67: =C67*SQRT(252) -> 0.25416482
A68: =returns_pnl[[#This Row],[price_date]] -> 45601 | B68: =returns_pnl[[#This Row],[portfolio_simple_return]] -> 0.017377667 | C68: =_xlfn.STDEV.S(B9:B68) -> 0.016133214 | D68: =C68*SQRT(252) -> 0.25610684
A69: =returns_pnl[[#This Row],[price_date]] -> 45602 | B69: =returns_pnl[[#This Row],[portfolio_simple_return]] -> 0.031364259 | C69: =_xlfn.STDEV.S(B10:B69) -> 0.016186524 | D69: =C69*SQRT(252) -> 0.2569531
A70: =returns_pnl[[#This Row],[price_date]] -> 45603 | B70: =returns_pnl[[#This Row],[portfolio_simple_return]] -> 0.014609501 | C70: =_xlfn.STDEV.S(B11:B70) -> 0.016242932 | D70: =C70*SQRT(252) -> 0.25784855
A71: =returns_pnl[[#This Row],[price_date]] -> 45604 | B71: =returns_pnl[[#This Row],[portfolio_simple_return]] -> 0.004817321 | C71: =_xlfn.STDEV.S(B12:B71) -> 0.015543937 | D71: =C71*SQRT(252) -> 0.24675235
A72: =returns_pnl[[#This Row],[price_date]] -> 45607 | B72: =returns_pnl[[#This Row],[portfolio_simple_return]] -> -0.003761761 | C72: =_xlfn.STDEV.S(B13:B72) -> 0.015560318 | D72: =C72*SQRT(252) -> 0.24701239
... A501: =returns_pnl[[#This Row],[price_date]] -> 46234 | B501: =returns_pnl[[#This Row],[portfolio_simple_return]] -> -0.000420364 | C501: =_xlfn.STDEV.S(B442:B501) -> 0.035163255 | D501: =C501*SQRT(252) -> 0.55819937

Sheet EWMA
A1: Date | B1: Portfolio Daily Return | C1: EWMA Daily Variance | D1: EWMA Daily Volatility | E1: EWMA Annualized Volatility | F1: 60 Daily Rolling Annnualized Volatility | G1: Lambda | Q1: Date | R1: AMD | S1: AVGO | T1: AXP | U1: LLY | V1: MRVL | W1: V | Y1: AMD VAR | Z1: AMD-AVGO COV | AA1: AMD-AXP COV | AB1: AMD-LLY COV | AC1: AMD-MRVL COV | AD1: AMD-V COV | AE1: AVGO VAR | AF1: AVGO-AXP COV | AG1: AVGO-LLY COV | AH1: AVGO-MRVL COV | AI1: AVGO-V COV | AJ1: AXP VAR | AK1: AXP-LLY COV | AL1: AXP-MRVL COV | AM1: AXP-V COV | AN1: LLY VAR | AO1: LLY-MRVL COV | AP1: LLY-V COV | AQ1: MRVL VAR | AR1: MRVL-V COV | AS1: V VAR | AU1: Date | AV1: DYNAMIC PORTFOLIO VARIANCE | AW1: DYNAMIC PORTFOLIO DAILY VOLATILITY | AX1: DYNAMIC 99% VaR(USD) | AY1: ACTUAL PORTFOLIO PnL (USD)
A2: =returns_pnl[[#This Row],[price_date]] -> 45506 | B2: =returns_pnl[[#This Row],[portfolio_simple_return]] -> -0.0298918 | G2: 0.94 | Q2: 45506 | R2: -0.000301796 | S2: -0.021765746 | T2: -0.065948207 | U2: -0.033612032 | V2: -0.060418649 | W2: 0.002444252 | AU2: 45506
A3: =returns_pnl[[#This Row],[price_date]] -> 45509 | B3: =returns_pnl[[#This Row],[portfolio_simple_return]] -> -0.020305629 | Q3: 45509 | R3: 0.017509434 | S3: -0.012098456 | T3: -0.027380747 | U3: -0.036297641 | V3: -0.026666667 | W3: -0.038037362 | AU3: 45509
A4: =returns_pnl[[#This Row],[price_date]] -> 45510 | B4: =returns_pnl[[#This Row],[portfolio_simple_return]] -> 0.006205662 | Q4: 45510 | R4: -0.034416259 | S4: 0.012950451 | T4: 0.023016997 | U4: 0.023114826 | V4: 0.009537021 | W4: 0.007097177 | AU4: 45510
A5: =returns_pnl[[#This Row],[price_date]] -> 45511 | B5: =returns_pnl[[#This Row],[portfolio_simple_return]] -> -0.023909427 | Q5: 45511 | R5: -0.011599324 | S5: -0.05315453 | T5: -0.010038076 | U5: -0.026526135 | V5: -0.035554792 | W5: -0.006737396 | AU5: 45511
A6: =returns_pnl[[#This Row],[price_date]] -> 45512 | B6: =returns_pnl[[#This Row],[portfolio_simple_return]] -> 0.057259208 | Q6: 45512 | R6: 0.059454418 | S6: 0.069494386 | T6: 0.020716783 | U6: 0.094762608 | V6: 0.089225289 | W6: 0.012903477 | AU6: 45512
A7: =returns_pnl[[#This Row],[price_date]] -> 45513 | B7: =returns_pnl[[#This Row],[portfolio_simple_return]] -> 0.010938891 | Q7: 45513 | R7: -0.015038146 | S7: 0.017291066 | T7: 0.018455083 | U7: 0.054855615 | V7: -0.009810334 | W7: -0.000269407 | AU7: 45513
A8: =returns_pnl[[#This Row],[price_date]] -> 45516 | B8: =returns_pnl[[#This Row],[portfolio_simple_return]] -> 0.001513824 | Q8: 45516 | R8: 0.0186192 | S8: 0.002428167 | T8: -0.003363464 | U8: -0.008186794 | V8: -0.000825628 | W8: 0.000500462 | AU8: 45516
A9: =returns_pnl[[#This Row],[price_date]] -> 45517 | B9: =returns_pnl[[#This Row],[portfolio_simple_return]] -> 0.029560735 | Q9: 45517 | R9: 0.031878336 | S9: 0.050733414 | T9: 0.008183927 | U9: 0.026764513 | V9: 0.058502727 | W9: 0.000923468 | AU9: 45517
A10: =returns_pnl[[#This Row],[price_date]] -> 45518 | B10: =returns_pnl[[#This Row],[portfolio_simple_return]] -> 0.008864891 | Q10: 45518 | R10: -0.002692553 | S10: 0.009797643 | T10: 0.019958994 | U10: 0.026022796 | V10: -0.004059329 | W10: 0.003882674 | AU10: 45518
A11: =returns_pnl[[#This Row],[price_date]] -> 45519 | B11: =returns_pnl[[#This Row],[portfolio_simple_return]] -> 0.03841872 | Q11: 45519 | R11: 0.0469627 | S11: 0.053522735 | T11: 0.023547752 | U11: -0.000107333 | V11: 0.086847468 | W11: 0.021674198 | AU11: 45519
A12: =returns_pnl[[#This Row],[price_date]] -> 45520 | B12: =returns_pnl[[#This Row],[portfolio_simple_return]] -> 0.000905754 | Q12: 45520 | R12: 0.008143323 | S12: -0.002467947 | T12: 0.008857715 | U12: -0.010154791 | V12: -0.000144238 | W12: 0.002173913 | AU12: 45520
A13: =returns_pnl[[#This Row],[price_date]] -> 45523 | B13: =returns_pnl[[#This Row],[portfolio_simple_return]] -> 0.015004267 | Q13: 45523 | R13: 0.045234249 | S13: 0.012008207 | T13: 0.009296413 | U13: -0.000336182 | V13: 0.024812464 | W13: -0.003403396 | AU13: 45523
A14: =returns_pnl[[#This Row],[price_date]] -> 45524 | B14: =returns_pnl[[#This Row],[portfolio_simple_return]] -> 0.000995652 | Q14: 45524 | R14: 0.007212777 | S14: -0.010494306 | T14: -0.003818146 | U14: 0.030548595 | V14: -0.02294482 | W14: 0.005891845 | AU14: 45524
... A60: =returns_pnl[[#This Row],[price_date]] -> 45589 | B60: =returns_pnl[[#This Row],[portfolio_simple_return]] -> -0.004426799 | Q60: 45589 | R60: 0.003466091 | S60: -0.01244885 | T60: -0.004608635 | U60: -0.013207861 | V60: 0.001222046 | W60: -0.001903017 | AU60: 45589
A61: =returns_pnl[[#This Row],[price_date]] -> 45590 | B61: =returns_pnl[[#This Row],[portfolio_simple_return]] -> 0.001849787 | C61: =_xlfn.VAR.S(B2:B61) -> 0.00031227369 | D61: =SQRT(C61) -> 0.017671267 | E61: =D61*SQRT(252) -> 0.28052267 | F61: =Rolling_Vol!D61 -> 0.28052267 | G61: 0.94 | Q61: 45590 | R61: 0.018183003 | S61: 0.009629414 | T61: -0.009741462 | U61: 0.001548266 | V61: -0.003905773 | W61: -0.005260928 | Y61: =_xlfn.VAR.S(R2:R61) -> 0.00073762333 | Z61: =_xlfn.COVARIANCE.S($R$2:$R$61,S2:S61) -> 0.0005882776 | AA61: =_xlfn.COVARIANCE.S($R$2:$R$61,T2:T61) -> 0.0001195596 | AB61: =_xlfn.COVARIANCE.S($R$2:$R$61,U2:U61) -> 0.00015632336 | AC61: =_xlfn.COVARIANCE.S($R$2:$R$61,V2:V61) -> 0.00060210235 | AD61: =_xlfn.COVARIANCE.S($R$2:$R$61,W2:W61) -> -9.8854027e-06 | AE61: =_xlfn.VAR.S(S2:S61) -> 0.00093160328 | AF61: =_xlfn.COVARIANCE.S($S$2:$S$61,T2:T61) -> 0.00023169378 | AG61: =_xlfn.COVARIANCE.S($S$2:$S$61,U2:U61) -> 0.0003142793 | AH61: =_xlfn.COVARIANCE.S($S$2:$S$61,V2:V61) -> 0.00074972792 | AI61: =_xlfn.COVARIANCE.S($S$2:$S$61,W2:W61) -> 3.9624376e-05 | AJ61: =_xlfn.VAR.S(T2:T61) -> 0.00031081862 | AK61: =_xlfn.COVARIANCE.S($T$2:$T$61,U2:U61) -> 0.00014966356 | AL61: =_xlfn.COVARIANCE.S($T$2:$T$61,V2:V61) -> 0.00026569963 | AM61: =_xlfn.COVARIANCE.S($T$2:$T$61,W2:W61) -> 6.2077071e-05 | AN61: =_xlfn.VAR.S(U2:U61) -> 0.00042744891 | AO61: =_xlfn.COVARIANCE.S($U$2:$U$61,V2:V61) -> 0.00030233874 | AP61: =_xlfn.COVARIANCE.S($U$2:$U$61,W2:W61) -> 3.9453852e-05 | AQ61: =_xlfn.VAR.S(V2:V61) -> 0.0011658765 | AR61: =_xlfn.COVARIANCE.S(V2:V61,W2:W61) -> 7.7872762e-05 | AS61: =_xlfn.VAR.S(W2:W61) -> 0.00015589006 | AU61: 45590 | AV61: =CovMatrix!$M$4^2*Y61 +CovMatrix!$M$5^2*AE61 +CovMatrix!$M$6^2*AJ61 +CovMatrix!$M$7^2*AN61 +CovMatrix!$M$8^2*AQ61 +CovMatrix!$M$9^2*AS61 +2*CovMatrix!$M$4*CovMatrix!$M$5*Z61 +2*CovMatrix!$M$4*CovMatrix!$M$6*AA61 +2*CovMatrix!$M$4*CovMatrix!$M$7*AB61 +2*CovMatrix!$M$4*CovMatrix!$M$8*AC61 +2*CovMatrix!$M$4*CovMatrix!$M$9*AD61 +2*CovMatrix!$M$5*CovMatrix!$M$6*AF61 +2*CovMatrix!$M$5*CovMatrix!$M$7*AG61 +2*CovMatrix!$M$5*CovMatrix!$M$8*AH61 +2*CovMatrix!$M$5*CovMatrix!$M$9*AI61 +2*CovMatrix!$M$6*CovMatrix!$M$7*AK61 +2*CovMatrix!$M$6*CovMatrix!$M$8*AL61 +2*CovMatrix!$M$6*CovMatrix!$M$9*AM61 +2*CovMatrix!$M$7*CovMatrix!$M$8*AO61 +2*CovMatrix!$M$7*CovMatrix!$M$9*AP61 +2*CovMatrix!$M$8*CovMatrix!$M$9*AR61 -> 0.0004329779 | AW61: =SQRT(AV61) -> 0.020808121 | AX61: =Param_VaR!$B$7*EWMA!AW61*returns_pnl[[#This Row],[port_mv]] -> 5532.6437 | AY61: =returns_pnl[[#This Row],[daily_pnl_usd]] -> 211.03
A62: =returns_pnl[[#This Row],[price_date]] -> 45593 | B62: =returns_pnl[[#This Row],[portfolio_simple_return]] -> 0.011602837 | C62: =C61*$G$61+(1-$G$61)*B61^2 -> 0.00029374257 | D62: =SQRT(C62) -> 0.01713892 | E62: =D62*SQRT(252) -> 0.27207192 | F62: =Rolling_Vol!D62 -> 0.27292151 | Q62: 45593 | R62: 0.023619023 | S62: -0.00566474 | T62: 0.015410511 | U62: 0.00323737 | V62: 0.022423723 | W62: 0.008731765 | Y62: =$G$2*Y61+((1-$G$2)*R61^2) -> 0.00071320322 | Z62: =$G$2*Z61+(1-$G$2)*R61*S61 -> 0.00056348644 | AA62: =$G$2*AA61+(1-$G$2)*R61*T61 -> 0.00010175828 | AB62: =$G$2*AB61+(1-$G$2)*R61*U61 -> 0.00014863309 | AC62: =$G$2*AC61+(1-$G$2)*R61*V61 -> 0.00056171509 | AD62: =$G$2*AD61+(1-$G$2)*R61*W61 -> -1.5031847e-05 | AE62: =$G$2*AE61+(1-$G$2)*S61*S61 -> 0.00088127062 | AF62: =$G$2*AF61+(1-$G$2)*S61*T61 -> 0.00021216388 | AG62: =$G$2*AG61+(1-$G$2)*S61*U61 -> 0.00029631708 | AH62: =$G$2*AH61+(1-$G$2)*S61*V61 -> 0.00070248763 | AI62: =$G$2*AI61+(1-$G$2)*S61*W61 -> 3.4207334e-05 | AJ62: =$G$2*AJ61+(1-$G$2)*T61*T61 -> 0.00029786327 | AK62: =$G$2*AK61+(1-$G$2)*T61*U61 -> 0.0001397788 | AL62: =$G$2*AL61+(1-$G$2)*T61*V61 -> 0.00025204053 | AM62: =$G$2*AM61+(1-$G$2)*T61*W61 -> 6.1427394e-05 | AN62: =$G$2*AN61+(1-$G$2)*U61*U61 -> 0.00040194581 | AO62: =$G$2*AO61+(1-$G$2)*U61*V61 -> 0.00028383558 | AP62: =$G$2*AP61+(1-$G$2)*U61*W61 -> 3.6597902e-05 | AQ62: =$G$2*AQ61+(1-$G$2)*V61*V61 -> 0.0010968392 | AR62: =$G$2*AR61+(1-$G$2)*V61*W61 -> 7.4433275e-05 | AS62: =$G$2*AS61+(1-$G$2)*W61*W61 -> 0.00014819729 | AU62: 45593 | AV62: =CovMatrix!$M$4^2*Y62 +CovMatrix!$M$5^2*AE62 +CovMatrix!$M$6^2*AJ62 +CovMatrix!$M$7^2*AN62 +CovMatrix!$M$8^2*AQ62 +CovMatrix!$M$9^2*AS62 +2*CovMatrix!$M$4*CovMatrix!$M$5*Z62 +2*CovMatrix!$M$4*CovMatrix!$M$6*AA62 +2*CovMatrix!$M$4*CovMatrix!$M$7*AB62 +2*CovMatrix!$M$4*CovMatrix!$M$8*AC62 +2*CovMatrix!$M$4*CovMatrix!$M$9*AD62 +2*CovMatrix!$M$5*CovMatrix!$M$6*AF62 +2*CovMatrix!$M$5*CovMatrix!$M$7*AG62 +2*CovMatrix!$M$5*CovMatrix!$M$8*AH62 +2*CovMatrix!$M$5*CovMatrix!$M$9*AI62 +2*CovMatrix!$M$6*CovMatrix!$M$7*AK62 +2*CovMatrix!$M$6*CovMatrix!$M$8*AL62 +2*CovMatrix!$M$6*CovMatrix!$M$9*AM62 +2*CovMatrix!$M$7*CovMatrix!$M$8*AO62 +2*CovMatrix!$M$7*CovMatrix!$M$9*AP62 +2*CovMatrix!$M$8*CovMatrix!$M$9*AR62 -> 0.00040825472 | AW62: =SQRT(AV62) -> 0.020205314 | AX62: =Param_VaR!$B$7*EWMA!AW62*returns_pnl[[#This Row],[port_mv]] -> 5434.6989 | AY62: =returns_pnl[[#This Row],[daily_pnl_usd]] -> 1326.14
A63: =returns_pnl[[#This Row],[price_date]] -> 45594 | B63: =returns_pnl[[#This Row],[portfolio_simple_return]] -> 0.016740529 | C63: =C62*$G$61+(1-$G$61)*B62^2 -> 0.00028419557 | D63: =SQRT(C63) -> 0.016858101 | E63: =D63*SQRT(252) -> 0.26761406 | F63: =Rolling_Vol!D63 -> 0.2699129 | Q63: 45594 | R63: 0.039582291 | S63: 0.041971864 | T63: -0.003830994 | U63: 0.008921493 | V63: 0.017138063 | W63: -0.008128365 | Y63: =$G$2*Y62+((1-$G$2)*R62^2) -> 0.00070388252 | Z63: =$G$2*Z62+(1-$G$2)*R62*S62 -> 0.00052164952 | AA63: =$G$2*AA62+(1-$G$2)*R62*T62 -> 0.00011749166 | AB63: =$G$2*AB62+(1-$G$2)*R62*U62 -> 0.00014430291 | AC63: =$G$2*AC62+(1-$G$2)*R62*V62 -> 0.00055978977 | AD63: =$G$2*AD62+(1-$G$2)*R62*W62 -> -1.7557904e-06 | AE63: =$G$2*AE62+(1-$G$2)*S62*S62 -> 0.00083031974 | AF63: =$G$2*AF62+(1-$G$2)*S62*T62 -> 0.00019419625 | AG63: =$G$2*AG62+(1-$G$2)*S62*U62 -> 0.00027743772 | AH63: =$G$2*AH62+(1-$G$2)*S62*V62 -> 0.0006527169 | AI63: =$G$2*AI62+(1-$G$2)*S62*W62 -> 2.9187103e-05 | AJ63: =$G$2*AJ62+(1-$G$2)*T62*T62 -> 0.00029424051 | AK63: =$G$2*AK62+(1-$G$2)*T62*U62 -> 0.00013438544 | AL63: =$G$2*AL62+(1-$G$2)*T62*V62 -> 0.00025765176 | AM63: =$G$2*AM62+(1-$G$2)*T62*W62 -> 6.5815408e-05 | AN63: =$G$2*AN62+(1-$G$2)*U62*U62 -> 0.00037845789 | AO63: =$G$2*AO62+(1-$G$2)*U62*V62 -> 0.00027116108 | AP63: =$G$2*AP62+(1-$G$2)*U62*W62 -> 3.6098105e-05 | AQ63: =$G$2*AQ62+(1-$G$2)*V62*V62 -> 0.0010611983 | AR63: =$G$2*AR62+(1-$G$2)*V62*W62 -> 8.17152e-05 | AS63: =$G$2*AS62+(1-$G$2)*W62*W62 -> 0.00014388008 | AU63: 45594 | AV63: =CovMatrix!$M$4^2*Y63 +CovMatrix!$M$5^2*AE63 +CovMatrix!$M$6^2*AJ63 +CovMatrix!$M$7^2*AN63 +CovMatrix!$M$8^2*AQ63 +CovMatrix!$M$9^2*AS63 +2*CovMatrix!$M$4*CovMatrix!$M$5*Z63 +2*CovMatrix!$M$4*CovMatrix!$M$6*AA63 +2*CovMatrix!$M$4*CovMatrix!$M$7*AB63 +2*CovMatrix!$M$4*CovMatrix!$M$8*AC63 +2*CovMatrix!$M$4*CovMatrix!$M$9*AD63 +2*CovMatrix!$M$5*CovMatrix!$M$6*AF63 +2*CovMatrix!$M$5*CovMatrix!$M$7*AG63 +2*CovMatrix!$M$5*CovMatrix!$M$8*AH63 +2*CovMatrix!$M$5*CovMatrix!$M$9*AI63 +2*CovMatrix!$M$6*CovMatrix!$M$7*AK63 +2*CovMatrix!$M$6*CovMatrix!$M$8*AL63 +2*CovMatrix!$M$6*CovMatrix!$M$9*AM63 +2*CovMatrix!$M$7*CovMatrix!$M$8*AO63 +2*CovMatrix!$M$7*CovMatrix!$M$9*AP63 +2*CovMatrix!$M$8*CovMatrix!$M$9*AR63 -> 0.00039399954 | AW63: =SQRT(AV63) -> 0.019849422 | AX63: =Param_VaR!$B$7*EWMA!AW63*returns_pnl[[#This Row],[port_mv]] -> 5428.3503 | AY63: =returns_pnl[[#This Row],[daily_pnl_usd]] -> 1935.55
A64: =returns_pnl[[#This Row],[price_date]] -> 45595 | B64: =returns_pnl[[#This Row],[portfolio_simple_return]] -> -0.029202981 | C64: =C63*$G$61+(1-$G$61)*B63^2 -> 0.00028395855 | D64: =SQRT(C64) -> 0.01685107 | E64: =D64*SQRT(252) -> 0.26750244 | F64: =Rolling_Vol!D64 -> 0.27813119 | Q64: 45595 | R64: -0.10616541 | S64: -0.014505691 | T64: 0.013497023 | U64: -0.062805728 | V64: -0.024390244 | W64: 0.029374202 | Y64: =$G$2*Y63+((1-$G$2)*R63^2) -> 0.00075565504 | Z64: =$G$2*Z63+(1-$G$2)*R63*S63 -> 0.0005900311 | AA64: =$G$2*AA63+(1-$G$2)*R63*T63 -> 0.00010134379 | AB64: =$G$2*AB63+(1-$G$2)*R63*U63 -> 0.00015683273 | AC64: =$G$2*AC63+(1-$G$2)*R63*V63 -> 0.00056690421 | AD64: =$G$2*AD63+(1-$G$2)*R63*W63 -> -2.0954802e-05 | AE64: =$G$2*AE63+(1-$G$2)*S63*S63 -> 0.0008861988 | AF64: =$G$2*AF63+(1-$G$2)*S63*T63 -> 0.00017289684 | AG64: =$G$2*AG63+(1-$G$2)*S63*U63 -> 0.00028325856 | AH64: =$G$2*AH63+(1-$G$2)*S63*V63 -> 0.00065671287 | AI64: =$G$2*AI63+(1-$G$2)*S63*W63 -> 6.9661193e-06 | AJ64: =$G$2*AJ63+(1-$G$2)*T63*T63 -> 0.00027746667 | AK64: =$G$2*AK63+(1-$G$2)*T63*U63 -> 0.00012427163 | AL64: =$G$2*AL63+(1-$G$2)*T63*V63 -> 0.00023825331 | AM64: =$G$2*AM63+(1-$G$2)*T63*W63 -> 6.3734867e-05 | AN64: =$G$2*AN63+(1-$G$2)*U63*U63 -> 0.000360526 | AO64: =$G$2*AO63+(1-$G$2)*U63*V63 -> 0.00026406524 | AP64: =$G$2*AP63+(1-$G$2)*U63*W63 -> 2.958119e-05 | AQ64: =$G$2*AQ63+(1-$G$2)*V63*V63 -> 0.0010151492 | AR64: =$G$2*AR63+(1-$G$2)*V63*W63 -> 6.8454022e-05 | AS64: =$G$2*AS63+(1-$G$2)*W63*W63 -> 0.00013921149 | AU64: 45595 | AV64: =CovMatrix!$M$4^2*Y64 +CovMatrix!$M$5^2*AE64 +CovMatrix!$M$6^2*AJ64 +CovMatrix!$M$7^2*AN64 +CovMatrix!$M$8^2*AQ64 +CovMatrix!$M$9^2*AS64 +2*CovMatrix!$M$4*CovMatrix!$M$5*Z64 +2*CovMatrix!$M$4*CovMatrix!$M$6*AA64 +2*CovMatrix!$M$4*CovMatrix!$M$7*AB64 +2*CovMatrix!$M$4*CovMatrix!$M$8*AC64 +2*CovMatrix!$M$4*CovMatrix!$M$9*AD64 +2*CovMatrix!$M$5*CovMatrix!$M$6*AF64 +2*CovMatrix!$M$5*CovMatrix!$M$7*AG64 +2*CovMatrix!$M$5*CovMatrix!$M$8*AH64 +2*CovMatrix!$M$5*CovMatrix!$M$9*AI64 +2*CovMatrix!$M$6*CovMatrix!$M$7*AK64 +2*CovMatrix!$M$6*CovMatrix!$M$8*AL64 +2*CovMatrix!$M$6*CovMatrix!$M$9*AM64 +2*CovMatrix!$M$7*CovMatrix!$M$8*AO64 +2*CovMatrix!$M$7*CovMatrix!$M$9*AP64 +2*CovMatrix!$M$8*CovMatrix!$M$9*AR64 -> 0.00040078584 | AW64: =SQRT(AV64) -> 0.020019636 | AX64: =Param_VaR!$B$7*EWMA!AW64*returns_pnl[[#This Row],[port_mv]] -> 5315.0167 | AY64: =returns_pnl[[#This Row],[daily_pnl_usd]] -> -3432.99
A65: =returns_pnl[[#This Row],[price_date]] -> 45596 | B65: =returns_pnl[[#This Row],[portfolio_simple_return]] -> -0.023541059 | C65: =C64*$G$61+(1-$G$61)*B64^2 -> 0.00031808988 | D65: =SQRT(C65) -> 0.017835075 | E65: =D65*SQRT(252) -> 0.28312303 | F65: =Rolling_Vol!D65 -> 0.2779794 | Q65: 45596 | R65: -0.030484522 | S65: -0.038892663 | T65: -0.014594279 | U65: -0.020181146 | V65: -0.032487923 | W65: -0.001068376 | Y65: =$G$2*Y64+((1-$G$2)*R64^2) -> 0.0013865814 | Z65: =$G$2*Z64+(1-$G$2)*R64*S64 -> 0.0006470294 | AA65: =$G$2*AA64+(1-$G$2)*R64*T64 -> 9.2881388e-06 | AB65: =$G$2*AB64+(1-$G$2)*R64*U64 -> 0.00054749053 | AC65: =$G$2*AC64+(1-$G$2)*R64*V64 -> 0.00068825398 | AD65: =$G$2*AD64+(1-$G$2)*R64*W64 -> -0.00020680897 | AE65: =$G$2*AE64+(1-$G$2)*S64*S64 -> 0.00084565178 | AF65: =$G$2*AF64+(1-$G$2)*S64*T64 -> 0.00015077601 | AG65: =$G$2*AG64+(1-$G$2)*S64*U64 -> 0.00032092547 | AH65: =$G$2*AH64+(1-$G$2)*S64*V64 -> 0.00063853794 | AI65: =$G$2*AI64+(1-$G$2)*S64*W64 -> -1.9017434e-05 | AJ65: =$G$2*AJ64+(1-$G$2)*T64*T64 -> 0.00027174884 | AK65: =$G$2*AK64+(1-$G$2)*T64*U64 -> 6.5953908e-05 | AL65: =$G$2*AL64+(1-$G$2)*T64*V64 -> 0.00020420637 | AM65: =$G$2*AM64+(1-$G$2)*T64*W64 -> 8.3698632e-05 | AN65: =$G$2*AN64+(1-$G$2)*U64*U64 -> 0.00057556801 | AO65: =$G$2*AO64+(1-$G$2)*U64*V64 -> 0.00034013215 | AP65: =$G$2*AP64+(1-$G$2)*U64*W64 -> -8.288577e-05 | AQ65: =$G$2*AQ64+(1-$G$2)*V64*V64 -> 0.00098993328 | AR65: =$G$2*AR64+(1-$G$2)*V64*W64 -> 2.1360143e-05 | AS65: =$G$2*AS64+(1-$G$2)*W64*W64 -> 0.00018262943 | AU65: 45596 | AV65: =CovMatrix!$M$4^2*Y65 +CovMatrix!$M$5^2*AE65 +CovMatrix!$M$6^2*AJ65 +CovMatrix!$M$7^2*AN65 +CovMatrix!$M$8^2*AQ65 +CovMatrix!$M$9^2*AS65 +2*CovMatrix!$M$4*CovMatrix!$M$5*Z65 +2*CovMatrix!$M$4*CovMatrix!$M$6*AA65 +2*CovMatrix!$M$4*CovMatrix!$M$7*AB65 +2*CovMatrix!$M$4*CovMatrix!$M$8*AC65 +2*CovMatrix!$M$4*CovMatrix!$M$9*AD65 +2*CovMatrix!$M$5*CovMatrix!$M$6*AF65 +2*CovMatrix!$M$5*CovMatrix!$M$7*AG65 +2*CovMatrix!$M$5*CovMatrix!$M$8*AH65 +2*CovMatrix!$M$5*CovMatrix!$M$9*AI65 +2*CovMatrix!$M$6*CovMatrix!$M$7*AK65 +2*CovMatrix!$M$6*CovMatrix!$M$8*AL65 +2*CovMatrix!$M$6*CovMatrix!$M$9*AM65 +2*CovMatrix!$M$7*CovMatrix!$M$8*AO65 +2*CovMatrix!$M$7*CovMatrix!$M$9*AP65 +2*CovMatrix!$M$8*CovMatrix!$M$9*AR65 -> 0.00046833305 | AW65: =SQRT(AV65) -> 0.021641004 | AX65: =Param_VaR!$B$7*EWMA!AW65*returns_pnl[[#This Row],[port_mv]] -> 5610.2193 | AY65: =returns_pnl[[#This Row],[daily_pnl_usd]] -> -2686.58
A66: =returns_pnl[[#This Row],[price_date]] -> 45597 | B66: =returns_pnl[[#This Row],[portfolio_simple_return]] -> 0.007811349 | C66: =C65*$G$61+(1-$G$61)*B65^2 -> 0.00033225538 | D66: =SQRT(C66) -> 0.018227874 | E66: =D66*SQRT(252) -> 0.28935852 | F66: =Rolling_Vol!D66 -> 0.25429548 | Q66: 45597 | R66: -0.015339765 | S66: -0.005006774 | T66: 0.009663803 | U66: -0.013028178 | V66: 0.058170016 | W66: 0.003070554 | Y66: =$G$2*Y65+((1-$G$2)*R65^2) -> 0.0013591449 | Z66: =$G$2*Z65+(1-$G$2)*R65*S65 -> 0.00067934509 | AA66: =$G$2*AA65+(1-$G$2)*R65*T65 -> 3.5424828e-05 | AB66: =$G$2*AB65+(1-$G$2)*R65*U65 -> 0.00055155385 | AC66: =$G$2*AC65+(1-$G$2)*R65*V65 -> 0.00070638147 | AD66: =$G$2*AD65+(1-$G$2)*R65*W65 -> -0.0001924463 | AE66: =$G$2*AE65+(1-$G$2)*S65*S65 -> 0.00088567102 | AF66: =$G$2*AF65+(1-$G$2)*S65*T65 -> 0.00017578607 | AG66: =$G$2*AG65+(1-$G$2)*S65*U65 -> 0.00034876386 | AH66: =$G$2*AH65+(1-$G$2)*S65*V65 -> 0.00067603817 | AI66: =$G$2*AI65+(1-$G$2)*S65*W65 -> -1.5383268e-05 | AJ66: =$G$2*AJ65+(1-$G$2)*T65*T65 -> 0.00026822349 | AK66: =$G$2*AK65+(1-$G$2)*T65*U65 -> 7.966843e-05 | AL66: =$G$2*AL65+(1-$G$2)*T65*V65 -> 0.00022040225 | AM66: =$G$2*AM65+(1-$G$2)*T65*W65 -> 7.9612245e-05 | AN66: =$G$2*AN65+(1-$G$2)*U65*U65 -> 0.00056547065 | AO66: =$G$2*AO65+(1-$G$2)*U65*V65 -> 0.00035906283 | AP66: =$G$2*AP65+(1-$G$2)*U65*W65 -> -7.6618961e-05 | AQ66: =$G$2*AQ65+(1-$G$2)*V65*V65 -> 0.00099386519 | AR66: =$G$2*AR65+(1-$G$2)*V65*W65 -> 2.2161094e-05 | AS66: =$G$2*AS65+(1-$G$2)*W65*W65 -> 0.00017174015 | AU66: 45597 | AV66: =CovMatrix!$M$4^2*Y66 +CovMatrix!$M$5^2*AE66 +CovMatrix!$M$6^2*AJ66 +CovMatrix!$M$7^2*AN66 +CovMatrix!$M$8^2*AQ66 +CovMatrix!$M$9^2*AS66 +2*CovMatrix!$M$4*CovMatrix!$M$5*Z66 +2*CovMatrix!$M$4*CovMatrix!$M$6*AA66 +2*CovMatrix!$M$4*CovMatrix!$M$7*AB66 +2*CovMatrix!$M$4*CovMatrix!$M$8*AC66 +2*CovMatrix!$M$4*CovMatrix!$M$9*AD66 +2*CovMatrix!$M$5*CovMatrix!$M$6*AF66 +2*CovMatrix!$M$5*CovMatrix!$M$7*AG66 +2*CovMatrix!$M$5*CovMatrix!$M$8*AH66 +2*CovMatrix!$M$5*CovMatrix!$M$9*AI66 +2*CovMatrix!$M$6*CovMatrix!$M$7*AK66 +2*CovMatrix!$M$6*CovMatrix!$M$8*AL66 +2*CovMatrix!$M$6*CovMatrix!$M$9*AM66 +2*CovMatrix!$M$7*CovMatrix!$M$8*AO66 +2*CovMatrix!$M$7*CovMatrix!$M$9*AP66 +2*CovMatrix!$M$8*CovMatrix!$M$9*AR66 -> 0.0004835311 | AW66: =SQRT(AV66) -> 0.021989341 | AX66: =Param_VaR!$B$7*EWMA!AW66*returns_pnl[[#This Row],[port_mv]] -> 5745.0509 | AY66: =returns_pnl[[#This Row],[daily_pnl_usd]] -> 870.47
A67: =returns_pnl[[#This Row],[price_date]] -> 45600 | B67: =returns_pnl[[#This Row],[portfolio_simple_return]] -> -0.005725731 | C67: =C66*$G$61+(1-$G$61)*B66^2 -> 0.00031598109 | D67: =SQRT(C67) -> 0.017775857 | E67: =D67*SQRT(252) -> 0.28218298 | F67: =Rolling_Vol!D67 -> 0.25416482 | Q67: 45600 | R67: -0.008106584 | S67: -0.002190386 | T67: -0.00916792 | U67: -0.015617941 | V67: -0.004600684 | W67: 0.003817844 | Y67: =$G$2*Y66+((1-$G$2)*R66^2) -> 0.0012917147 | Z67: =$G$2*Z66+(1-$G$2)*R66*S66 -> 0.00064319255 | AA67: =$G$2*AA66+(1-$G$2)*R66*T66 -> 2.440491e-05 | AB67: =$G$2*AB66+(1-$G$2)*R66*U66 -> 0.00053045157 | AC67: =$G$2*AC66+(1-$G$2)*R66*V66 -> 0.00061045972 | AD67: =$G$2*AD66+(1-$G$2)*R66*W66 -> -0.00018372561 | AE67: =$G$2*AE66+(1-$G$2)*S66*S66 -> 0.00083403483 | AF67: =$G$2*AF66+(1-$G$2)*S66*T66 -> 0.00016233584 | AG67: =$G$2*AG66+(1-$G$2)*S66*U66 -> 0.00033175177 | AH67: =$G$2*AH66+(1-$G$2)*S66*V66 -> 0.00061800124 | AI67: =$G$2*AI66+(1-$G$2)*S66*W66 -> -1.5382687e-05 | AJ67: =$G$2*AJ66+(1-$G$2)*T66*T66 -> 0.00025773343 | AK67: =$G$2*AK66+(1-$G$2)*T66*U66 -> 6.7334219e-05 | AL67: =$G$2*AL66+(1-$G$2)*T66*V66 -> 0.00024090673 | AM67: =$G$2*AM66+(1-$G$2)*T66*W66 -> 7.6615904e-05 | AN67: =$G$2*AN66+(1-$G$2)*U66*U66 -> 0.00054172641 | AO67: =$G$2*AO66+(1-$G$2)*U66*V66 -> 0.0002920481 | AP67: =$G$2*AP66+(1-$G$2)*U66*W66 -> -7.4422047e-05 | AQ67: =$G$2*AQ66+(1-$G$2)*V66*V66 -> 0.0011372583 | AR67: =$G$2*AR66+(1-$G$2)*V66*W66 -> 3.1548279e-05 | AS67: =$G$2*AS66+(1-$G$2)*W66*W66 -> 0.00016200144 | AU67: 45600 | AV67: =CovMatrix!$M$4^2*Y67 +CovMatrix!$M$5^2*AE67 +CovMatrix!$M$6^2*AJ67 +CovMatrix!$M$7^2*AN67 +CovMatrix!$M$8^2*AQ67 +CovMatrix!$M$9^2*AS67 +2*CovMatrix!$M$4*CovMatrix!$M$5*Z67 +2*CovMatrix!$M$4*CovMatrix!$M$6*AA67 +2*CovMatrix!$M$4*CovMatrix!$M$7*AB67 +2*CovMatrix!$M$4*CovMatrix!$M$8*AC67 +2*CovMatrix!$M$4*CovMatrix!$M$9*AD67 +2*CovMatrix!$M$5*CovMatrix!$M$6*AF67 +2*CovMatrix!$M$5*CovMatrix!$M$7*AG67 +2*CovMatrix!$M$5*CovMatrix!$M$8*AH67 +2*CovMatrix!$M$5*CovMatrix!$M$9*AI67 +2*CovMatrix!$M$6*CovMatrix!$M$7*AK67 +2*CovMatrix!$M$6*CovMatrix!$M$8*AL67 +2*CovMatrix!$M$6*CovMatrix!$M$9*AM67 +2*CovMatrix!$M$7*CovMatrix!$M$8*AO67 +2*CovMatrix!$M$7*CovMatrix!$M$9*AP67 +2*CovMatrix!$M$8*CovMatrix!$M$9*AR67 -> 0.00045815627 | AW67: =SQRT(AV67) -> 0.021404585 | AX67: =Param_VaR!$B$7*EWMA!AW67*returns_pnl[[#This Row],[port_mv]] -> 5560.2548 | AY67: =returns_pnl[[#This Row],[daily_pnl_usd]] -> -643.04
A68: =returns_pnl[[#This Row],[price_date]] -> 45601 | B68: =returns_pnl[[#This Row],[portfolio_simple_return]] -> 0.017377667 | C68: =C67*$G$61+(1-$G$61)*B67^2 -> 0.00029898926 | D68: =SQRT(C68) -> 0.017291306 | E68: =D68*SQRT(252) -> 0.27449097 | F68: =Rolling_Vol!D68 -> 0.25610684 | Q68: 45601 | R68: 0.006751475 | S68: 0.031741323 | T68: 0.021281321 | U68: -9.92383e-05 | V68: 0.03330173 | W68: 0.004934042 | Y68: =$G$2*Y67+((1-$G$2)*R67^2) -> 0.0012181548 | Z68: =$G$2*Z67+(1-$G$2)*R67*S67 -> 0.00060566639 | AA68: =$G$2*AA67+(1-$G$2)*R67*T67 -> 2.7399846e-05 | AB68: =$G$2*AB67+(1-$G$2)*R67*U67 -> 0.00050622097 | AC68: =$G$2*AC67+(1-$G$2)*R67*V67 -> 0.00057606988 | AD68: =$G$2*AD67+(1-$G$2)*R67*W67 -> -0.00017455906 | AE68: =$G$2*AE67+(1-$G$2)*S67*S67 -> 0.00078428061 | AF68: =$G$2*AF67+(1-$G$2)*S67*T67 -> 0.00015380057 | AG68: =$G$2*AG67+(1-$G$2)*S67*U67 -> 0.00031389923 | AH68: =$G$2*AH67+(1-$G$2)*S67*V67 -> 0.0005815258 | AI68: =$G$2*AI67+(1-$G$2)*S67*W67 -> -1.4961478e-05 | AJ68: =$G$2*AJ67+(1-$G$2)*T67*T67 -> 0.00024731247 | AK68: =$G$2*AK67+(1-$G$2)*T67*U67 -> 7.1885208e-05 | AL68: =$G$2*AL67+(1-$G$2)*T67*V67 -> 0.00022898305 | AM68: =$G$2*AM67+(1-$G$2)*T67*W67 -> 6.9918848e-05 | AN68: =$G$2*AN67+(1-$G$2)*U67*U67 -> 0.00052385803 | AO68: =$G$2*AO67+(1-$G$2)*U67*V67 -> 0.00027883641 | AP68: =$G$2*AP67+(1-$G$2)*U67*W67 -> -7.3534336e-05 | AQ68: =$G$2*AQ67+(1-$G$2)*V67*V67 -> 0.0010702928 | AR68: =$G$2*AR67+(1-$G$2)*V67*W67 -> 2.86015e-05 | AS68: =$G$2*AS67+(1-$G$2)*W67*W67 -> 0.00015315591 | AU68: 45601 | AV68: =CovMatrix!$M$4^2*Y68 +CovMatrix!$M$5^2*AE68 +CovMatrix!$M$6^2*AJ68 +CovMatrix!$M$7^2*AN68 +CovMatrix!$M$8^2*AQ68 +CovMatrix!$M$9^2*AS68 +2*CovMatrix!$M$4*CovMatrix!$M$5*Z68 +2*CovMatrix!$M$4*CovMatrix!$M$6*AA68 +2*CovMatrix!$M$4*CovMatrix!$M$7*AB68 +2*CovMatrix!$M$4*CovMatrix!$M$8*AC68 +2*CovMatrix!$M$4*CovMatrix!$M$9*AD68 +2*CovMatrix!$M$5*CovMatrix!$M$6*AF68 +2*CovMatrix!$M$5*CovMatrix!$M$7*AG68 +2*CovMatrix!$M$5*CovMatrix!$M$8*AH68 +2*CovMatrix!$M$5*CovMatrix!$M$9*AI68 +2*CovMatrix!$M$6*CovMatrix!$M$7*AK68 +2*CovMatrix!$M$6*CovMatrix!$M$8*AL68 +2*CovMatrix!$M$6*CovMatrix!$M$9*AM68 +2*CovMatrix!$M$7*CovMatrix!$M$8*AO68 +2*CovMatrix!$M$7*CovMatrix!$M$9*AP68 +2*CovMatrix!$M$8*CovMatrix!$M$9*AR68 -> 0.00043268476 | AW68: =SQRT(AV68) -> 0.020801076 | AX68: =Param_VaR!$B$7*EWMA!AW68*returns_pnl[[#This Row],[port_mv]] -> 5497.3815 | AY68: =returns_pnl[[#This Row],[daily_pnl_usd]] -> 1940.46
A69: =returns_pnl[[#This Row],[price_date]] -> 45602 | B69: =returns_pnl[[#This Row],[portfolio_simple_return]] -> 0.031364259 | C69: =C68*$G$61+(1-$G$61)*B68^2 -> 0.0002991689 | D69: =SQRT(C69) -> 0.0172965 | E69: =D69*SQRT(252) -> 0.27457342 | F69: =Rolling_Vol!D69 -> 0.2569531 | Q69: 45602 | R69: 0.024283496 | S69: 0.032489937 | T69: 0.069652823 | U69: -0.03682108 | V69: 0.039454066 | W69: 0.04810938 | Y69: =$G$2*Y68+((1-$G$2)*R68^2) -> 0.0011478005 | Z69: =$G$2*Z68+(1-$G$2)*R68*S68 -> 0.00058218445 | AA69: =$G$2*AA68+(1-$G$2)*R68*T68 -> 3.4376674e-05 | AB69: =$G$2*AB68+(1-$G$2)*R68*U68 -> 0.00047580751 | AC69: =$G$2*AC68+(1-$G$2)*R68*V68 -> 0.00055499584 | AD69: =$G$2*AD68+(1-$G$2)*R68*W68 -> -0.00016208679 | AE69: =$G$2*AE68+(1-$G$2)*S68*S68 -> 0.00079767447 | AF69: =$G$2*AF68+(1-$G$2)*S68*T68 -> 0.00018510237 | AG69: =$G$2*AG68+(1-$G$2)*S68*U68 -> 0.00029487628 | AH69: =$G$2*AH68+(1-$G$2)*S68*V68 -> 0.00061005671 | AI69: =$G$2*AI68+(1-$G$2)*S68*W68 -> -4.6670085e-06 | AJ69: =$G$2*AJ68+(1-$G$2)*T68*T68 -> 0.0002596474 | AK69: =$G$2*AK68+(1-$G$2)*T68*U68 -> 6.744538e-05 | AL69: =$G$2*AL68+(1-$G$2)*T68*V68 -> 0.00025776636 | AM69: =$G$2*AM68+(1-$G$2)*T68*W68 -> 7.2023893e-05 | AN69: =$G$2*AN68+(1-$G$2)*U68*U68 -> 0.00049242714 | AO69: =$G$2*AO68+(1-$G$2)*U68*V68 -> 0.00026190794 | AP69: =$G$2*AP68+(1-$G$2)*U68*W68 -> -6.9151654e-05 | AQ69: =$G$2*AQ68+(1-$G$2)*V68*V68 -> 0.0010726155 | AR69: =$G$2*AR68+(1-$G$2)*V68*W68 -> 3.6744138e-05 | AS69: =$G$2*AS68+(1-$G$2)*W68*W68 -> 0.00014542724 | AU69: 45602 | AV69: =CovMatrix!$M$4^2*Y69 +CovMatrix!$M$5^2*AE69 +CovMatrix!$M$6^2*AJ69 +CovMatrix!$M$7^2*AN69 +CovMatrix!$M$8^2*AQ69 +CovMatrix!$M$9^2*AS69 +2*CovMatrix!$M$4*CovMatrix!$M$5*Z69 +2*CovMatrix!$M$4*CovMatrix!$M$6*AA69 +2*CovMatrix!$M$4*CovMatrix!$M$7*AB69 +2*CovMatrix!$M$4*CovMatrix!$M$8*AC69 +2*CovMatrix!$M$4*CovMatrix!$M$9*AD69 +2*CovMatrix!$M$5*CovMatrix!$M$6*AF69 +2*CovMatrix!$M$5*CovMatrix!$M$7*AG69 +2*CovMatrix!$M$5*CovMatrix!$M$8*AH69 +2*CovMatrix!$M$5*CovMatrix!$M$9*AI69 +2*CovMatrix!$M$6*CovMatrix!$M$7*AK69 +2*CovMatrix!$M$6*CovMatrix!$M$8*AL69 +2*CovMatrix!$M$6*CovMatrix!$M$9*AM69 +2*CovMatrix!$M$7*CovMatrix!$M$8*AO69 +2*CovMatrix!$M$7*CovMatrix!$M$9*AP69 +2*CovMatrix!$M$8*CovMatrix!$M$9*AR69 -> 0.00042659366 | AW69: =SQRT(AV69) -> 0.020654144 | AX69: =Param_VaR!$B$7*EWMA!AW69*returns_pnl[[#This Row],[port_mv]] -> 5629.7532 | AY69: =returns_pnl[[#This Row],[daily_pnl_usd]] -> 3563.12
A70: =returns_pnl[[#This Row],[price_date]] -> 45603 | B70: =returns_pnl[[#This Row],[portfolio_simple_return]] -> 0.014609501 | C70: =C69*$G$61+(1-$G$61)*B69^2 -> 0.00034024177 | D70: =SQRT(C70) -> 0.018445644 | E70: =D70*SQRT(252) -> 0.29281552 | F70: =Rolling_Vol!D70 -> 0.25784855 | Q70: 45603 | R70: 0.03252929 | S70: 0.023725982 | T70: -0.028255861 | U70: 0.027138772 | V70: 0.036522123 | W70: -0.005204945 | Y70: =$G$2*Y69+((1-$G$2)*R69^2) -> 0.0011143138 | Z70: =$G$2*Z69+(1-$G$2)*R69*S69 -> 0.00059459154 | AA70: =$G$2*AA69+(1-$G$2)*R69*T69 -> 0.00013379892 | AB70: =$G$2*AB69+(1-$G$2)*R69*U69 -> 0.00039361039 | AC70: =$G$2*AC69+(1-$G$2)*R69*V69 -> 0.00057918105 | AD70: =$G$2*AD69+(1-$G$2)*R69*W69 -> -8.2265748e-05 | AE70: =$G$2*AE69+(1-$G$2)*S69*S69 -> 0.00081314976 | AF70: =$G$2*AF69+(1-$G$2)*S69*T69 -> 0.00030977718 | AG70: =$G$2*AG69+(1-$G$2)*S69*U69 -> 0.00020540482 | AH70: =$G$2*AH69+(1-$G$2)*S69*V69 -> 0.00065036491 | AI70: =$G$2*AI69+(1-$G$2)*S69*W69 -> 8.9397256e-05 | AJ70: =$G$2*AJ69+(1-$G$2)*T69*T69 -> 0.0005351595 | AK70: =$G$2*AK69+(1-$G$2)*T69*U69 -> -9.0482873e-05 | AL70: =$G$2*AL69+(1-$G$2)*T69*V69 -> 0.0004071856 | AM70: =$G$2*AM69+(1-$G$2)*T69*W69 -> 0.00026875971 | AN70: =$G$2*AN69+(1-$G$2)*U69*U69 -> 0.00054422903 | AO70: =$G$2*AO69+(1-$G$2)*U69*V69 -> 0.00015902898 | AP70: =$G$2*AP69+(1-$G$2)*U69*W69 -> -0.00017128891 | AQ70: =$G$2*AQ69+(1-$G$2)*V69*V69 -> 0.001101656 | AR70: =$G$2*AR69+(1-$G$2)*V69*W69 -> 0.00014842613 | AS70: =$G$2*AS69+(1-$G$2)*W69*W69 -> 0.00027557235 | AU70: 45603 | AV70: =CovMatrix!$M$4^2*Y70 +CovMatrix!$M$5^2*AE70 +CovMatrix!$M$6^2*AJ70 +CovMatrix!$M$7^2*AN70 +CovMatrix!$M$8^2*AQ70 +CovMatrix!$M$9^2*AS70 +2*CovMatrix!$M$4*CovMatrix!$M$5*Z70 +2*CovMatrix!$M$4*CovMatrix!$M$6*AA70 +2*CovMatrix!$M$4*CovMatrix!$M$7*AB70 +2*CovMatrix!$M$4*CovMatrix!$M$8*AC70 +2*CovMatrix!$M$4*CovMatrix!$M$9*AD70 +2*CovMatrix!$M$5*CovMatrix!$M$6*AF70 +2*CovMatrix!$M$5*CovMatrix!$M$7*AG70 +2*CovMatrix!$M$5*CovMatrix!$M$8*AH70 +2*CovMatrix!$M$5*CovMatrix!$M$9*AI70 +2*CovMatrix!$M$6*CovMatrix!$M$7*AK70 +2*CovMatrix!$M$6*CovMatrix!$M$8*AL70 +2*CovMatrix!$M$6*CovMatrix!$M$9*AM70 +2*CovMatrix!$M$7*CovMatrix!$M$8*AO70 +2*CovMatrix!$M$7*CovMatrix!$M$9*AP70 +2*CovMatrix!$M$8*CovMatrix!$M$9*AR70 -> 0.00045516681 | AW70: =SQRT(AV70) -> 0.021334639 | AX70: =Param_VaR!$B$7*EWMA!AW70*returns_pnl[[#This Row],[port_mv]] -> 5900.1951 | AY70: =returns_pnl[[#This Row],[daily_pnl_usd]] -> 1711.76
